2021-01-05 17:36:10,924 INFO: waiting 30 sec...
2021-01-05 17:37:54,868 INFO: waiting 30 sec...
2021-01-05 17:38:24,870 INFO: reconnect
2021-01-05 17:38:47,307 INFO: waiting 30 sec...
2021-01-05 17:39:17,309 INFO: reconnect
2021-01-05 17:39:42,738 INFO: waiting 30 sec...
2021-01-05 17:40:12,739 INFO: reconnect
2021-01-05 17:40:35,626 INFO: waiting 30 sec...
2021-01-05 17:41:05,626 INFO: reconnect
2021-01-05 17:41:28,074 INFO: waiting 30 sec...
2021-01-05 17:41:58,074 INFO: reconnect
2021-01-05 17:42:20,520 INFO: waiting 30 sec...
2021-01-05 17:42:50,523 INFO: reconnect
2021-01-05 17:43:12,926 INFO: waiting 30 sec...
2021-01-05 17:43:42,926 INFO: reconnect
2021-01-05 17:44:06,361 INFO: waiting 30 sec...
2021-01-05 17:44:36,367 INFO: reconnect
2021-01-05 17:45:01,785 INFO: waiting 30 sec...
2021-01-05 17:45:31,786 INFO: reconnect
2021-01-05 17:45:55,766 INFO: waiting 30 sec...
2021-01-05 17:46:25,768 INFO: reconnect
2021-01-05 17:46:48,197 INFO: waiting 30 sec...
2021-01-05 17:47:18,197 INFO: reconnect
2021-01-05 17:47:41,025 INFO: waiting 30 sec...
2021-01-05 17:48:11,026 INFO: reconnect
2021-01-05 17:48:33,436 INFO: waiting 30 sec...
2021-01-05 17:49:03,437 INFO: reconnect
2021-01-05 17:49:35,323 INFO: waiting 30 sec...
2021-01-05 17:50:05,323 INFO: reconnect
2021-01-05 17:50:29,009 ERROR: 
Traceback (most recent call last):
  File "C:/DCG/GitHub/dcg-edi/ftp_demo.py", line 103, in DownloadFile
    res = ftp.retrbinary('RETR %s' % dst_filename, f.write) if f.tell() == 0 else \
  File "C:\Users\thoma\AppData\Local\Programs\Python\Python38\lib\ftplib.py", line 425, in retrbinary
    with self.transfercmd(cmd, rest) as conn:
  File "C:\Users\thoma\AppData\Local\Programs\Python\Python38\lib\ftplib.py", line 382, in transfercmd
    return self.ntransfercmd(cmd, rest)[0]
  File "C:\Users\thoma\AppData\Local\Programs\Python\Python38\lib\ftplib.py", line 343, in ntransfercmd
    conn = socket.create_connection((host, port), self.timeout,
  File "C:\Users\thoma\AppData\Local\Programs\Python\Python38\lib\socket.py", line 808, in create_connection
    raise err
  File "C:\Users\thoma\AppData\Local\Programs\Python\Python38\lib\socket.py", line 796, in create_connection
    sock.connect(sa)
TimeoutError: [WinError 10060] A connection attempt failed because the connected party did not properly respond after a period of time, or established connection failed because connected host has failed to respond
2021-01-05 17:54:47,350 INFO: waiting 30 sec...
2021-01-05 17:58:37,235 INFO: waiting 30 sec...
2021-01-05 17:59:07,236 INFO: reconnect
2021-01-05 17:59:29,681 INFO: waiting 30 sec...
2021-01-05 17:59:59,681 INFO: reconnect
2021-01-05 18:00:23,118 INFO: waiting 30 sec...
2021-01-05 18:00:53,118 INFO: reconnect
2021-01-05 18:01:16,821 INFO: waiting 30 sec...
2021-01-05 18:01:46,822 INFO: reconnect
2021-01-05 18:02:09,254 INFO: waiting 30 sec...
2021-01-05 18:02:39,254 INFO: reconnect
2021-01-05 18:03:02,123 INFO: waiting 30 sec...
2021-01-05 18:03:32,124 INFO: reconnect
2021-01-05 18:03:55,121 INFO: waiting 30 sec...
2021-01-05 18:04:25,121 INFO: reconnect
2021-01-05 18:04:48,003 INFO: waiting 30 sec...
2021-01-05 18:05:18,003 INFO: reconnect
2021-01-05 18:05:40,433 INFO: waiting 30 sec...
2021-01-05 18:06:10,433 INFO: reconnect
2021-01-05 18:06:32,830 INFO: waiting 30 sec...
2021-01-05 18:07:02,832 INFO: reconnect
2021-01-05 18:07:25,832 INFO: waiting 30 sec...
2021-01-05 18:07:55,833 INFO: reconnect
2021-01-05 18:08:18,665 INFO: waiting 30 sec...
2021-01-05 18:08:48,665 INFO: reconnect
2021-01-05 18:09:11,500 INFO: waiting 30 sec...
2021-01-05 18:09:41,500 INFO: reconnect
2021-01-05 18:10:06,646 INFO: waiting 30 sec...
2021-01-05 18:10:36,647 INFO: reconnect
2021-01-05 18:10:59,075 ERROR: 
Traceback (most recent call last):
  File "C:/DCG/GitHub/dcg-edi/ftp_demo.py", line 103, in DownloadFile
    res = ftp.retrbinary('RETR %s' % dst_filename, f.write) if f.tell() == 0 else \
  File "C:\Users\thoma\AppData\Local\Programs\Python\Python38\lib\ftplib.py", line 425, in retrbinary
    with self.transfercmd(cmd, rest) as conn:
  File "C:\Users\thoma\AppData\Local\Programs\Python\Python38\lib\ftplib.py", line 382, in transfercmd
    return self.ntransfercmd(cmd, rest)[0]
  File "C:\Users\thoma\AppData\Local\Programs\Python\Python38\lib\ftplib.py", line 343, in ntransfercmd
    conn = socket.create_connection((host, port), self.timeout,
  File "C:\Users\thoma\AppData\Local\Programs\Python\Python38\lib\socket.py", line 808, in create_connection
    raise err
  File "C:\Users\thoma\AppData\Local\Programs\Python\Python38\lib\socket.py", line 796, in create_connection
    sock.connect(sa)
TimeoutError: [WinError 10060] A connection attempt failed because the connected party did not properly respond after a period of time, or established connection failed because connected host has failed to respond
2021-01-06 08:54:10,520 INFO: waiting 30 sec...
2021-01-06 08:54:40,521 INFO: reconnect
2021-01-06 08:55:02,921 INFO: waiting 30 sec...
2021-01-06 08:55:32,922 INFO: reconnect
2021-01-06 08:55:58,332 INFO: waiting 30 sec...
2021-01-06 09:43:20,748 INFO: waiting 30 sec...
2021-01-06 09:43:50,748 INFO: reconnect
2021-01-06 09:44:13,159 INFO: waiting 30 sec...
2021-01-06 09:44:43,160 INFO: reconnect
2021-01-06 10:21:43,569 INFO: waiting 30 sec...
2021-01-06 10:22:13,570 INFO: reconnect
