2021-01-05 17:36:10,924 INFO: waiting 30 sec...
2021-01-05 17:37:54,868 INFO: waiting 30 sec...
2021-01-05 17:38:24,870 INFO: reconnect
2021-01-05 17:38:47,307 INFO: waiting 30 sec...
2021-01-05 17:39:17,309 INFO: reconnect
2021-01-05 17:39:42,738 INFO: waiting 30 sec...
2021-01-05 17:40:12,739 INFO: reconnect
2021-01-05 17:40:35,626 INFO: waiting 30 sec...
2021-01-05 17:41:05,626 INFO: reconnect
2021-01-05 17:41:28,074 INFO: waiting 30 sec...
2021-01-05 17:41:58,074 INFO: reconnect
2021-01-05 17:42:20,520 INFO: waiting 30 sec...
2021-01-05 17:42:50,523 INFO: reconnect
2021-01-05 17:43:12,926 INFO: waiting 30 sec...
2021-01-05 17:43:42,926 INFO: reconnect
2021-01-05 17:44:06,361 INFO: waiting 30 sec...
2021-01-05 17:44:36,367 INFO: reconnect
2021-01-05 17:45:01,785 INFO: waiting 30 sec...
2021-01-05 17:45:31,786 INFO: reconnect
2021-01-05 17:45:55,766 INFO: waiting 30 sec...
2021-01-05 17:46:25,768 INFO: reconnect
2021-01-05 17:46:48,197 INFO: waiting 30 sec...
2021-01-05 17:47:18,197 INFO: reconnect
2021-01-05 17:47:41,025 INFO: waiting 30 sec...
2021-01-05 17:48:11,026 INFO: reconnect
2021-01-05 17:48:33,436 INFO: waiting 30 sec...
2021-01-05 17:49:03,437 INFO: reconnect
2021-01-05 17:49:35,323 INFO: waiting 30 sec...
2021-01-05 17:50:05,323 INFO: reconnect
2021-01-05 17:50:29,009 ERROR: 
Traceback (most recent call last):
  File "C:/DCG/GitHub/dcg-edi/ftp_demo.py", line 103, in DownloadFile
    res = ftp.retrbinary('RETR %s' % dst_filename, f.write) if f.tell() == 0 else \
  File "C:\Users\thoma\AppData\Local\Programs\Python\Python38\lib\ftplib.py", line 425, in retrbinary
    with self.transfercmd(cmd, rest) as conn:
  File "C:\Users\thoma\AppData\Local\Programs\Python\Python38\lib\ftplib.py", line 382, in transfercmd
    return self.ntransfercmd(cmd, rest)[0]
  File "C:\Users\thoma\AppData\Local\Programs\Python\Python38\lib\ftplib.py", line 343, in ntransfercmd
    conn = socket.create_connection((host, port), self.timeout,
  File "C:\Users\thoma\AppData\Local\Programs\Python\Python38\lib\socket.py", line 808, in create_connection
    raise err
  File "C:\Users\thoma\AppData\Local\Programs\Python\Python38\lib\socket.py", line 796, in create_connection
    sock.connect(sa)
TimeoutError: [WinError 10060] A connection attempt failed because the connected party did not properly respond after a period of time, or established connection failed because connected host has failed to respond
